Workbook

Sheet About
A1: Active state name: | B1: Washington | C1: 46184
A2: Active state code: | B2: =INDEX(Geography!B:B, MATCH(B1, Geography!C:C, 0)) -> WA
A3: Active state FIPS: | B3: =INDEX(Geography!A:A, MATCH(B2, Geography!B:B, 0)) -> 53
A4: Active NEMS division #: | B4: =INDEX(Geography!D:D, MATCH(B2, Geography!B:B, 0)) -> 9
A5: Active NEMS division label: | B5: =INDEX(Geography!E:E, MATCH(B2, Geography!B:B, 0)) -> 9 Pacific | C5: (matches the labels used in NEMS_residential col B / NEMS_commercial col B)
A6: Active state HH: | B6: =INDEX(State_demographics!D:D, MATCH(B2, State_demographics!A:A, 0)) -> 3168080
A7: Active state commercial floor (sqft): | B7: =INDEX(State_demographics!E:E, MATCH(B2, State_demographics!A:A, 0)) -> 1.772637e+09
A8: Active state urban share (%): | B8: =INDEX(State_demographics!F:F, MATCH(B2, State_demographics!A:A, 0)) -> 83.371846
A9: Active state rural share (%): | B9: =INDEX(State_demographics!G:G, MATCH(B2, State_demographics!A:A, 0)) -> 16.628154
A10: Division HH (denominator): | B10: =SUMIF(State_demographics!$C$2:$C$49, $B$4, State_demographics!$D$2:$D$49) -> 18709988 | C10: (SUMIF over the 48 state rows of State_demographics, summed by active NEMS division #)
A11: Division floor (denominator, sqft): | B11: =SUMIF(State_demographics!$C$2:$C$49, $B$4, State_demographics!$E$2:$E$49) -> 1.2044315e+10
A12: State HH share within division: | B12: =B6/B10 -> 0.1693256
A13: State floor share within division: | B13: =B7/B11 -> 0.14717624
A15: Workbook
A16: State-level capex on building components (heating, cooling+vent, lighting, appliances) 2024-2050.
A17: Drop-in input for the EPS state model at InputData/bldgs/BASoBC/.
A19: Method (Option A): division NEMS capex x state share within division.
A20: Residential: state_HH_share x national-NEMS division capex. Urban/rural split per state (2020 Census).
A21: Commercial: state_floor_share x national-NEMS division capex.
A23: Envelope and "other component" output = 0 (NEMS source does not report these).
A25: Methodology: docs/methodology/BASoBC.md
A26: Generator: outputs/buildings/_build_BASoBC_workbook.py
A29: state_BASoBC — State BAU Amount Spent on Building Components
A31: Built: 2026-06-08 15:28
A32: Scope: 48 contiguous U.S. states, 2024-2050.
... A47: Generator: outputs/buildings/_build_BASoBC_workbook.py

Sheet Methodology
A1: Methodology summary
A3: Inputs
A4: * NEMS division x component x year capex (residential + commercial) — embedded from the EPS national BASoBC source file (AEO 2015 vintage). 9 census divisions.
A5: * State household counts: ACS 2024 1-year (sources/processed/acs/acs2024_state_housing.csv).
A6: * State commercial floorspace: QCEW-derived 2024 (sources/processed/qcew/state_commercial_floorspace_2024.csv).
A7: * State urban/rural shares: 2020 Census decennial (sources/raw/census/State_Urban_Rural_Pop_2020_2010.xlsx).
A8: * State -> Census division: config/geography/state_to_census_division.csv (using aeo_division_num, the 9-region scheme matching NEMS).
A9: Aggregation: NEMS source -> (division, component, year)
A10: * Source data is row-per-(division, building_type, end_use, fuel, equipment_type). For each (division, EPS_component, year), SUMIFS over all rows where Sum of TOTINVEST applies (residential) or the subtotal rows are present (commercial).
A11: * Component mapping: NEMS end_use -> EPS component per the source mapping tab (e.g. Cooking -> appliances; Cooling -> cooling and ventilation).
A12: * Helper "division_filled" column on NEMS source tabs fills the pivot-style division header downward so SUMIFS can filter by division.
A13: Downscale: division -> state
... A30: * Active state selector: About!B2 (2-letter code). About!B1 displays the derived full state name.

Sheet Sources
A1: Sources for state_BASoBC.xlsx
A3: All citations require staff verification against the primary source before external use, per organizational guidance.
A5: Organization | B5: Dataset | C5: URL | D5: Vintage / Note
A6: U.S. Energy Information Administration | B6: NEMS "Amount Spent on Components" — division x building x end_use x fuel x equipment_type x year | C6: https://www.eia.gov/outlooks/aeo/ | D6: AEO 2015 vintage; available on request from EIA. Embedded via the EPS national BASoBC file (eps-us/InputData/bldgs/BASoBC/).
A7: U.S. Energy Information Administration | B7: Assumptions to the Annual Energy Outlook 2026: Residential Demand Module — Table 4 (per-division rebate percentages) | C7: https://www.eia.gov/outlooks/aeo/assumptions/pdf/RDM_Assumptions.pdf | D7: April 2026. Used to populate the AEO_RDM_rebates reference tab. Confirms NEMS subtracts division-level utility incentives + federal tax credits from sticker cost before reporting TOTINVEST.
A8: U.S. Census Bureau | B8: American Community Survey 1-Year Estimates, DP04 (Selected Housing Characteristics) | C8: https://data.census.gov/table?d=ACS+1-Year+Estimates+Selected+Population+Profiles&tid=ACSDP1Y2024.DP04 | D8: 2024 release. Used: occupied_housing_units per state.
A9: U.S. Bureau of Labor Statistics | B9: Quarterly Census of Employment and Wages (QCEW) state x NAICS sector x ownership | C9: https://www.bls.gov/cew/downloadable-data-files.htm | D9: 2024 annual averages, agglvl 54. Used to derive state commercial floorspace allocation (sources/processed/qcew/state_commercial_floorspace_2024.csv).
A10: U.S. Census Bureau | B10: 2020 Decennial Census, State Urban and Rural Population | C10: https://www.census.gov/programs-surveys/decennial-census/about/urban-rural.html | D10: 2020 release. Used: per-state urban/rural pop %.
A11: U.S. Bureau of Labor Statistics | B11: Consumer Price Index (CPI-U all items) | C11: https://www.bls.gov/cpi/data.htm | D11: CPI 2017 -> 2012 deflator = 0.9367 (per EPS national BASoBC source About tab).

Sheet Geography
A1: state_fips | B1: state_abbr | C1: state_name | D1: nems_division_num | E1: nems_division_label
A2: 01 | B2: AL | C2: Alabama | D2: 6 | E2: 6 East South Central
A3: 04 | B3: AZ | C3: Arizona | D3: 8 | E3: 8 Mountain
A4: 05 | B4: AR | C4: Arkansas | D4: 7 | E4: 7 West South Central
A5: 06 | B5: CA | C5: California | D5: 9 | E5: 9 Pacific
A6: 08 | B6: CO | C6: Colorado | D6: 8 | E6: 8 Mountain
A7: 09 | B7: CT | C7: Connecticut | D7: 1 | E7: 1 New England
A8: 10 | B8: DE | C8: Delaware | D8: 5 | E8: 5 South Atlantic
A9: 12 | B9: FL | C9: Florida | D9: 5 | E9: 5 South Atlantic
A10: 13 | B10: GA | C10: Georgia | D10: 5 | E10: 5 South Atlantic
A11: 16 | B11: ID | C11: Idaho | D11: 8 | E11: 8 Mountain
A12: 17 | B12: IL | C12: Illinois | D12: 3 | E12: 3 East North Central
A13: 18 | B13: IN | C13: Indiana | D13: 3 | E13: 3 East North Central
... A49: 56 | B49: WY | C49: Wyoming | D49: 8 | E49: 8 Mountain

Sheet State_demographics
A1: state_abbr | B1: state_name | C1: nems_division_num | D1: state_HH | E1: state_commercial_floor_sqft | F1: state_urban_share_pct | G1: state_rural_share_pct
A2: AL | B2: Alabama | C2: 6 | D2: 2059528 | E2: 1.2667742e+09 | F2: 57.73724 | G2: 42.26276
A3: AZ | B3: Arizona | C3: 8 | D3: 2982475 | E3: 2.0326988e+09 | F3: 89.28516 | G3: 10.71484
A4: AR | B4: Arkansas | C4: 7 | D4: 1246754 | E4: 7.4451156e+08 | F4: 55.476131 | G4: 44.523869
A5: CA | B5: California | C5: 9 | D5: 13797638 | E5: 9290924823 | F5: 94.236633 | G5: 5.7633673
A6: CO | B6: Colorado | C6: 8 | D6: 2479892 | E6: 1.8821231e+09 | F6: 86.026707 | G6: 13.973293
A7: CT | B7: Connecticut | C7: 1 | D7: 1455235 | E7: 8.5116782e+08 | F7: 86.250729 | G7: 13.749271
A8: DE | B8: Delaware | C8: 5 | D8: 412304 | E8: 2.6248924e+08 | F8: 82.612117 | G8: 17.387883
A9: FL | B9: Florida | C9: 5 | D9: 9141675 | E9: 6.1924183e+09 | F9: 91.534195 | G9: 8.4658054
A10: GA | B10: Georgia | C10: 5 | D10: 4220732 | E10: 2.8914578e+09 | F10: 74.066973 | G10: 25.933027
A11: ID | B11: Idaho | C11: 8 | D11: 751181 | E11: 5.2050958e+08 | F11: 69.242175 | G11: 30.757825
A12: IL | B12: Illinois | C12: 3 | D12: 5105448 | E12: 5.0949735e+09 | F12: 86.927477 | G12: 13.072523
A13: IN | B13: Indiana | C13: 3 | D13: 2775637 | E13: 2.4486121e+09 | F13: 71.176274 | G13: 28.823726
... A49: WY | B49: Wyoming | C49: 8 | D49: 256289 | E49: 1.6866885e+08 | F49: 62.017748 | G49: 37.982252
A51: Division totals (SUMIF helpers for downscale denominator):
A52: nems_division_num | B52: nems_division_label | C52: division_HH | D52: division_floor_sqft
A53: 1 | B53: 1 New England | C53: =SUMIF(C2:C49, A53, D2:D49) -> 6204829 | D53: =SUMIF(C2:C49, A53, E2:E49) -> 3760333030
A54: 2 | B54: 2 Middle Atlantic | C54: =SUMIF(C2:C49, A54, D2:D49) -> 16733742 | D54: =SUMIF(C2:C49, A54, E2:E49) -> 1.2225747e+10
A55: 3 | B55: 3 East North Central | C55: =SUMIF(C2:C49, A55, D2:D49) -> 19476886 | D55: =SUMIF(C2:C49, A55, E2:E49) -> 1.748009e+10
A56: 4 | B56: 4 West North Central | C56: =SUMIF(C2:C49, A56, D2:D49) -> 9030501 | D56: =SUMIF(C2:C49, A56, E2:E49) -> 8.4870475e+09
A57: 5 | B57: 5 South Atlantic | C57: =SUMIF(C2:C49, A57, D2:D49) -> 27085501 | D57: =SUMIF(C2:C49, A57, E2:E49) -> 1.7934672e+10
A58: 6 | B58: 6 East South Central | C58: =SUMIF(C2:C49, A58, D2:D49) -> 8030439 | D58: =SUMIF(C2:C49, A58, E2:E49) -> 5.4278296e+09
A59: 7 | B59: 7 West South Central | C59: =SUMIF(C2:C49, A59, D2:D49) -> 16149236 | D59: =SUMIF(C2:C49, A59, E2:E49) -> 1.157908e+10
A60: 8 | B60: 8 Mountain | C60: =SUMIF(C2:C49, A60, D2:D49) -> 10219141 | D60: =SUMIF(C2:C49, A60, E2:E49) -> 7.5880825e+09
A61: 9 | B61: 9 Pacific | C61: =SUMIF(C2:C49, A61, D2:D49) -> 18709988 | D61: =SUMIF(C2:C49, A61, E2:E49) -> 1.2044315e+10

Sheet Keys
A1: category | B1: key | C1: value | D1: description
A2: unit | B2: cpi_2017_to_2012 | C2: 0.9366596 | D2: CPI deflator 2017 USD -> 2012 USD (NEMS data is in 2017$ per source)
A3: unit | B3: billions_to_dollars | C3: 1000000000 | D3: Commercial NEMS data is in billions of 2017$; multiply by 1e9 to get $
A4: label | B4: sum_of_totinvest | C4: Sum of TOTINVEST | D4: NEMS Residential data label for total capital expenditure
A5: component | B5: heating | C5: heating
A6: component | B6: cooling_and_ventilation | C6: cooling and ventilation
A7: component | B7: lighting | C7: lighting
A8: component | B8: appliances | C8: appliances
A9: component | B9: envelope | C9: envelope | D9: NEMS does not report; output = 0
A10: component | B10: other_component | C10: other component | D10: NEMS does not report; output = 0
A11: division | B11: div_1 | C11: 1 New England
A12: division | B12: div_2 | C12: 2 Middle Atlantic
A13: division | B13: div_3 | C13: 3 East North Central
A14: division | B14: div_4 | C14: 4 West North Central
A15: division | B15: div_5 | C15: 5 South Atlantic
A16: division | B16: div_6 | C16: 6 East South Central
A17: division | B17: div_7 | C17: 7 West South Central
A18: division | B18: div_8 | C18: 8 Mountain
A19: division | B19: div_9 | C19: 9 Pacific

Sheet NEMS_residential
B1: Displays Investment and Subsidy on the Shell and Investment Tables -- note total expenditures on equipment or shell = consumer investment ("Investment") + subsidy; subsidy includes both federal and non-federal subsidies
B2: i.e., total investment = totinvest + totsubsidy ; investments are in RTEKDOLLARYR dollars (currently 2017$)
B3: Displays Investment and Subsidy on the Shell and Investment Tables -- note total expenditures on equipment or shell = consumer investment ("Investment") + subsidy.
B4: i.e., total investment = totinvest + totsubsidy
H5: YEAR
A6: mapping | B6: CDIV | C6: BLDG | D6: ENDUSE | E6: FUEL | F6: EQPTYPE | G6: Data | H6: 2016 | I6: 2017 | J6: 2018 | K6: 2019 | L6: 2020 | M6: 2021 | N6: 2022 | O6: 2023 | P6: 2024 | Q6: 2025 | R6: 2026 | S6: 2027 | T6: 2028 | U6: 2029 | V6: 2030 | W6: 2031 | X6: 2032 | Y6: 2033 | Z6: 2034 | AA6: 2035 | AB6: 2036 | AC6: 2037 | AD6: 2038 | AE6: 2039 | AF6: 2040 | AG6: 2041 | AH6: 2042 | AI6: 2043 | AJ6: 2044 | AK6: 2045 | AL6: 2046 | AM6: 2047 | AN6: 2048 | AO6: 2049 | AP6: 2050 | DH6: division_filled
A7: =IFERROR(INDEX(NEMS_mapping!C$3:C$12,MATCH(NEMS_residential!D7,NEMS_mapping!B$3:B$12,0)),A6) -> appliances | B7: 1 New England | C7: Single Family | D7: Cooking | E7: Electricity | F7: ELEC_STV2 | G7: Sum of TOTSUBSIDY | H7: 0 | I7: 0 | J7: 0 | K7: 0 | L7: 0 | M7: 0 | N7: 0 | O7: 0 | P7: 0 | Q7: 0 | R7: 0 | S7: 0 | T7: 0 | U7: 0 | V7: 0 | W7: 0 | X7: 0 | Y7: 0 | Z7: 0 | AA7: 0 | AB7: 0 | AC7: 0 | AD7: 0 | AE7: 0 | AF7: 0 | AG7: 0 | AH7: 0 | AI7: 0 | AJ7: 0 | AK7: 0 | AL7: 0 | AM7: 0 | AN7: 0 | AO7: 0 | AP7: 0 | DH7: =B7 -> 1 New England
A8: =IFERROR(INDEX(NEMS_mapping!C$3:C$12,MATCH(NEMS_residential!D8,NEMS_mapping!B$3:B$12,0)),A7) -> appliances | G8: Sum of TOTPURCHASE | H8: 91893 | I8: 90934 | J8: 91587 | K8: 92942 | L8: 97784 | M8: 102590 | N8: 113733 | O8: 117654 | P8: 124238 | Q8: 130918 | R8: 138592 | S8: 148098 | T8: 158204 | U8: 181957 | V8: 206949 | W8: 236279 | X8: 267562 | Y8: 251651 | Z8: 222109 | AA8: 191161 | AB8: 154786 | AC8: 115987 | AD8: 124280 | AE8: 132612 | AF8: 141355 | AG8: 150325 | AH8: 159248 | AI8: 168058 | AJ8: 176273 | AK8: 183259 | AL8: 188425 | AM8: 191359 | AN8: 191724 | AO8: 189631 | AP8: 185357 | DH8: =IF(B8<>"", B8, DH7) -> 1 New England
A9: =IFERROR(INDEX(NEMS_mapping!C$3:C$12,MATCH(NEMS_residential!D9,NEMS_mapping!B$3:B$12,0)),A8) -> appliances | G9: Sum of TOTINVEST | H9: 59731125 | I9: 59107502 | J9: 59532301 | K9: 60412722 | L9: 63560000 | M9: 66684231 | N9: 73926573 | O9: 76475947 | P9: 80755795 | Q9: 85097366 | R9: 90085590 | S9: 96264187 | T9: 102833036 | U9: 118272624 | V9: 134517617 | W9: 153582460 | X9: 173916075 | Y9: 163573552 | Z9: 144370956 | AA9: 124255634 | AB9: 100611961 | AC9: 75391992 | AD9: 80782508 | AE9: 86198394 | AF9: 91881717 | AG9: 97712399 | AH9: 103512223 | AI9: 109238841 | AJ9: 114578131 | AK9: 119119150 | AL9: 122477262 | AM9: 124383763 | AN9: 124620885 | AO9: 123260623 | AP9: 120482333 | DH9: =IF(B9<>"", B9, DH8) -> 1 New England
A10: =IFERROR(INDEX(NEMS_mapping!C$3:C$12,MATCH(NEMS_residential!D10,NEMS_mapping!B$3:B$12,0)),A9) -> appliances | E10: Natural Gas | F10: NG_STV2 | G10: Sum of TOTSUBSIDY | H10: 0 | I10: 0 | J10: 0 | K10: 0 | L10: 0 | M10: 0 | N10: 0 | O10: 0 | P10: 0 | Q10: 0 | R10: 0 | S10: 0 | T10: 0 | U10: 0 | V10: 0 | W10: 0 | X10: 0 | Y10: 0 | Z10: 0 | AA10: 0 | AB10: 0 | AC10: 0 | AD10: 0 | AE10: 0 | AF10: 0 | AG10: 0 | AH10: 0 | AI10: 0 | AJ10: 0 | AK10: 0 | AL10: 0 | AM10: 0 | AN10: 0 | AO10: 0 | AP10: 0 | DH10: =IF(B10<>"", B10, DH9) -> 1 New England
A11: =IFERROR(INDEX(NEMS_mapping!C$3:C$12,MATCH(NEMS_residential!D11,NEMS_mapping!B$3:B$12,0)),A10) -> appliances | G11: Sum of TOTPURCHASE | H11: 41927 | I11: 43493 | J11: 44035 | K11: 45830 | L11: 49250 | M11: 49513 | N11: 52863 | O11: 54643 | P11: 58405 | Q11: 62523 | R11: 68837 | S11: 77378 | T11: 85858 | U11: 95202 | V11: 104223 | W11: 112027 | X11: 118193 | Y11: 110766 | Z11: 102572 | AA11: 94111 | AB11: 85569 | AC11: 77398 | AD11: 83044 | AE11: 89476 | AF11: 96568 | AG11: 103702 | AH11: 110112 | AI11: 115198 | AJ11: 118210 | AK11: 118686 | AL11: 116808 | AM11: 113245 | AN11: 109218 | AO11: 105966 | AP11: 104598 | DH11: =IF(B11<>"", B11, DH10) -> 1 New England
A12: =IFERROR(INDEX(NEMS_mapping!C$3:C$12,MATCH(NEMS_residential!D12,NEMS_mapping!B$3:B$12,0)),A11) -> appliances | G12: Sum of TOTINVEST | H12: 10901285 | I12: 11308325 | J12: 11449390 | K12: 11916143 | L12: 12805152 | M12: 12873525 | N12: 13744703 | O12: 14207401 | P12: 15185694 | Q12: 16256363 | R12: 17897886 | S12: 20118478 | T12: 22323547 | U12: 24752693 | V12: 27098467 | W12: 29127382 | X12: 30730461 | Y12: 28799586 | Z12: 26668820 | AA12: 24469025 | AB12: 22248051 | AC12: 20123700 | AD12: 21591758 | AE12: 23264121 | AF12: 25107997 | AG12: 26962873 | AH12: 28629334 | AI12: 29951659 | AJ12: 30734912 | AK12: 30858769 | AL12: 30370164 | AM12: 29444135 | AN12: 28396812 | AO12: 27551423 | AP12: 27195724 | DH12: =IF(B12<>"", B12, DH11) -> 1 New England
A13: =IFERROR(INDEX(NEMS_mapping!C$3:C$12,MATCH(NEMS_residential!D13,NEMS_mapping!B$3:B$12,0)),A12) -> appliances | F13: NG_STV4 | G13: Sum of TOTSUBSIDY | H13: 0 | I13: 0 | J13: 0 | K13: 0 | L13: 0 | M13: 0 | N13: 0 | O13: 0 | P13: 0 | Q13: 0 | R13: 0 | S13: 0 | T13: 0 | U13: 0 | V13: 0 | W13: 0 | X13: 0 | Y13: 0 | Z13: 0 | AA13: 0 | AB13: 0 | AC13: 0 | AD13: 0 | AE13: 0 | AF13: 0 | AG13: 0 | AH13: 0 | AI13: 0 | AJ13: 0 | AK13: 0 | AL13: 0 | AM13: 0 | AN13: 0 | AO13: 0 | AP13: 0 | DH13: =IF(B13<>"", B13, DH12) -> 1 New England
A14: =IFERROR(INDEX(NEMS_mapping!C$3:C$12,MATCH(NEMS_residential!D14,NEMS_mapping!B$3:B$12,0)),A13) -> appliances | G14: Sum of TOTPURCHASE | H14: 18701 | I14: 19506 | J14: 20537 | K14: 20944 | L14: 22347 | M14: 23043 | N14: 26434 | O14: 26764 | P14: 27366 | Q14: 28744 | R14: 31311 | S14: 34892 | T14: 38486 | U14: 42669 | V14: 46695 | W14: 50183 | X14: 52951 | Y14: 49635 | Z14: 45975 | AA14: 42193 | AB14: 38396 | AC14: 34771 | AD14: 37375 | AE14: 40307 | AF14: 43563 | AG14: 46845 | AH14: 49775 | AI14: 52081 | AJ14: 53412 | AK14: 53687 | AL14: 52836 | AM14: 51220 | AN14: 49387 | AO14: 47935 | AP14: 47355 | DH14: =IF(B14<>"", B14, DH13) -> 1 New England
A15: =IFERROR(INDEX(NEMS_mapping!C$3:C$12,MATCH(NEMS_residential!D15,NEMS_mapping!B$3:B$12,0)),A14) -> appliances | G15: Sum of TOTINVEST | H15: 5618793 | I15: 5860743 | J15: 6170627 | K15: 6292672 | L15: 6714259 | M15: 6923474 | N15: 7942203 | O15: 8041302 | P15: 8222370 | Q15: 8636333 | R15: 9407497 | S15: 10483280 | T15: 11563181 | U15: 12820179 | V15: 14029715 | W15: 15077244 | X15: 15909118 | Y15: 14912954 | Z15: 13813038 | AA15: 12677159 | AB15: 11536178 | AC15: 10447272 | AD15: 11229305 | AE15: 12110323 | AF15: 13088317 | AG15: 14074643 | AH15: 14954824 | AI15: 15647771 | AJ15: 16047776 | AK15: 16130380 | AL15: 15874713 | AM15: 15388996 | AN15: 14838458 | AO15: 14402148 | AP15: 14228091 | DH15: =IF(B15<>"", B15, DH14) -> 1 New England
A16: =IFERROR(INDEX(NEMS_mapping!C$3:C$12,MATCH(NEMS_residential!D16,NEMS_mapping!B$3:B$12,0)),A15) -> appliances | E16: LPG | F16: LPG_STV2 | G16: Sum of TOTSUBSIDY | H16: 0 | I16: 0 | J16: 0 | K16: 0 | L16: 0 | M16: 0 | N16: 0 | O16: 0 | P16: 0 | Q16: 0 | R16: 0 | S16: 0 | T16: 0 | U16: 0 | V16: 0 | W16: 0 | X16: 0 | Y16: 0 | Z16: 0 | AA16: 0 | AB16: 0 | AC16: 0 | AD16: 0 | AE16: 0 | AF16: 0 | AG16: 0 | AH16: 0 | AI16: 0 | AJ16: 0 | AK16: 0 | AL16: 0 | AM16: 0 | AN16: 0 | AO16: 0 | AP16: 0 | DH16: =IF(B16<>"", B16, DH15) -> 1 New England
A17: =IFERROR(INDEX(NEMS_mapping!C$3:C$12,MATCH(NEMS_residential!D17,NEMS_mapping!B$3:B$12,0)),A16) -> appliances | G17: Sum of TOTPURCHASE | H17: 28302 | I17: 30026 | J17: 30093 | K17: 31828 | L17: 33152 | M17: 37258 | N17: 28140 | O17: 28281 | P17: 29490 | Q17: 31602 | R17: 35239 | S17: 40144 | T17: 44890 | U17: 49711 | V17: 54146 | W17: 57477 | X17: 59439 | Y17: 54312 | Z17: 48873 | AA17: 43192 | AB17: 37601 | AC17: 32489 | AD17: 34321 | AE17: 36832 | AF17: 39686 | AG17: 42525 | AH17: 44967 | AI17: 46690 | AJ17: 47361 | AK17: 46786 | AL17: 45081 | AM17: 42600 | AN17: 39927 | AO17: 37723 | AP17: 36464 | DH17: =IF(B17<>"", B17, DH16) -> 1 New England
A18: =IFERROR(INDEX(NEMS_mapping!C$3:C$12,MATCH(NEMS_residential!D18,NEMS_mapping!B$3:B$12,0)),A17) -> appliances | G18: Sum of TOTINVEST | H18: 7358681 | I18: 7806992 | J18: 7824457 | K18: 8275675 | L18: 8619855 | M18: 9687317 | N18: 7316577 | O18: 7353387 | P18: 7667647 | Q18: 8216909 | R18: 9162344 | S18: 10437755 | T18: 11671472 | U18: 12925262 | V18: 14078077 | W18: 14944370 | X18: 15454474 | Y18: 14121354 | Z18: 12707211 | AA18: 11230382 | AB18: 9776550 | AC18: 8447533 | AD18: 8923713 | AE18: 9576558 | AF18: 10318408 | AG18: 11056728 | AH18: 11691710 | AI18: 12139588 | AJ18: 12314039 | AK18: 12164676 | AL18: 11721264 | AM18: 11076264 | AN18: 10381377 | AO18: 9808098 | AP18: 9480982 | DH18: =IF(B18<>"", B18, DH17) -> 1 New England
A19: =IFERROR(INDEX(NEMS_mapping!C$3:C$12,MATCH(NEMS_residential!D19,NEMS_mapping!B$3:B$12,0)),A18) -> appliances | F19: LPG_STV4 | G19: Sum of TOTSUBSIDY | H19: 0 | I19: 0 | J19: 0 | K19: 0 | L19: 0 | M19: 0 | N19: 0 | O19: 0 | P19: 0 | Q19: 0 | R19: 0 | S19: 0 | T19: 0 | U19: 0 | V19: 0 | W19: 0 | X19: 0 | Y19: 0 | Z19: 0 | AA19: 0 | AB19: 0 | AC19: 0 | AD19: 0 | AE19: 0 | AF19: 0 | AG19: 0 | AH19: 0 | AI19: 0 | AJ19: 0 | AK19: 0 | AL19: 0 | AM19: 0 | AN19: 0 | AO19: 0 | AP19: 0 | DH19: =IF(B19<>"", B19, DH18) -> 1 New England
A20: =IFERROR(INDEX(NEMS_mapping!C$3:C$12,MATCH(NEMS_residential!D20,NEMS_mapping!B$3:B$12,0)),A19) -> appliances | G20: Sum of TOTPURCHASE | H20: 14149 | I20: 14850 | J20: 16222 | K20: 16444 | L20: 16337 | M20: 19971 | N20: 17423 | O20: 18348 | P20: 19241 | Q20: 20145 | R20: 21918 | S20: 24467 | T20: 27036 | U20: 29805 | V20: 32531 | W20: 34766 | X20: 36341 | Y20: 33657 | Z20: 30690 | AA20: 27410 | AB20: 24048 | AC20: 20922 | AD20: 22296 | AE20: 24030 | AF20: 26069 | AG20: 28122 | AH20: 29878 | AI20: 31097 | AJ20: 31561 | AK20: 31217 | AL20: 30093 | AM20: 28458 | AN20: 26717 | AO20: 25253 | AP20: 24402 | DH20: =IF(B20<>"", B20, DH19) -> 1 New England
A21: =IFERROR(INDEX(NEMS_mapping!C$3:C$12,MATCH(NEMS_residential!D21,NEMS_mapping!B$3:B$12,0)),A20) -> appliances | G21: Sum of TOTINVEST | H21: 4251280 | I21: 4461926 | J21: 4873869 | K21: 4941012 | L21: 4908546 | M21: 6000344 | N21: 5235130 | O21: 5512862 | P21: 5781149 | Q21: 6052528 | R21: 6585328 | S21: 7351111 | T21: 8123137 | U21: 8954984 | V21: 9773958 | W21: 10445619 | X21: 10918891 | Y21: 10112308 | Z21: 9221178 | AA21: 8235443 | AB21: 7225317 | AC21: 6286190 | AD21: 6699164 | AE21: 7219838 | AF21: 7832740 | AG21: 8449459 | AH21: 8976992 | AI21: 9343208 | AJ21: 9482836 | AK21: 9379318 | AL21: 9041503 | AM21: 8550323 | AN21: 8027237 | AO21: 7587651 | AP21: 7331810 | DH21: =IF(B21<>"", B21, DH20) -> 1 New England
A22: =IFERROR(INDEX(NEMS_mapping!C$3:C$12,MATCH(NEMS_residential!D22,NEMS_mapping!B$3:B$12,0)),A21) -> cooling and ventilation | D22: Cooling | E22: Electricity | F22: CENT_AIR1 | G22: Sum of TOTSUBSIDY | H22: 0 | I22: 0 | J22: 0 | K22: 0 | L22: 0 | M22: 0 | N22: 0 | O22: 0 | P22: 0 | Q22: 0 | R22: 0 | S22: 0 | T22: 0 | U22: 0 | V22: 0 | W22: 0 | X22: 0 | Y22: 0 | Z22: 0 | AA22: 0 | AB22: 0 | AC22: 0 | AD22: 0 | AE22: 0 | AF22: 0 | AG22: 0 | AH22: 0 | AI22: 0 | AJ22: 0 | AK22: 0 | AL22: 0 | AM22: 0 | AN22: 0 | AO22: 0 | AP22: 0 | DH22: =IF(B22<>"", B22, DH21) -> 1 New England
A23: =IFERROR(INDEX(NEMS_mapping!C$3:C$12,MATCH(NEMS_residential!D23,NEMS_mapping!B$3:B$12,0)),A22) -> cooling and ventilation | G23: Sum of TOTPURCHASE | H23: 33760 | I23: 37383 | J23: 35156 | K23: 37446 | L23: 38727 | M23: 41772 | N23: 18949 | O23: 0 | P23: 0 | Q23: 0 | R23: 0 | S23: 0 | T23: 0 | U23: 0 | V23: 0 | W23: 0 | X23: 0 | Y23: 0 | Z23: 0 | AA23: 0 | AB23: 0 | AC23: 0 | AD23: 0 | AE23: 0 | AF23: 0 | AG23: 0 | AH23: 0 | AI23: 0 | AJ23: 0 | AK23: 0 | AL23: 0 | AM23: 0 | AN23: 0 | AO23: 0 | AP23: 0 | DH23: =IF(B23<>"", B23, DH22) -> 1 New England
A24: =IFERROR(INDEX(NEMS_mapping!C$3:C$12,MATCH(NEMS_residential!D24,NEMS_mapping!B$3:B$12,0)),A23) -> cooling and ventilation | G24: Sum of TOTINVEST | H24: 74273564 | I24: 82245592 | J24: 77346278 | K24: 82383488 | L24: 85200310 | M24: 91901896 | N24: 41689372 | O24: 0 | P24: 0 | Q24: 0 | R24: 0 | S24: 0 | T24: 0 | U24: 0 | V24: 0 | W24: 0 | X24: 0 | Y24: 0 | Z24: 0 | AA24: 0 | AB24: 0 | AC24: 0 | AD24: 0 | AE24: 0 | AF24: 0 | AG24: 0 | AH24: 0 | AI24: 0 | AJ24: 0 | AK24: 0 | AL24: 0 | AM24: 0 | AN24: 0 | AO24: 0 | AP24: 0 | DH24: =IF(B24<>"", B24, DH23) -> 1 New England
A25: =IFERROR(INDEX(NEMS_mapping!C$3:C$12,MATCH(NEMS_residential!D25,NEMS_mapping!B$3:B$12,0)),A24) -> cooling and ventilation | F25: CENT_AIR2 | G25: Sum of TOTSUBSIDY | H25: 0 | I25: 0 | J25: 0 | K25: 0 | L25: 0 | M25: 0 | N25: 0 | O25: 0 | P25: 0 | Q25: 0 | R25: 0 | S25: 0 | T25: 0 | U25: 0 | V25: 0 | W25: 0 | X25: 0 | Y25: 0 | Z25: 0 | AA25: 0 | AB25: 0 | AC25: 0 | AD25: 0 | AE25: 0 | AF25: 0 | AG25: 0 | AH25: 0 | AI25: 0 | AJ25: 0 | AK25: 0 | AL25: 0 | AM25: 0 | AN25: 0 | AO25: 0 | AP25: 0 | DH25: =IF(B25<>"", B25, DH24) -> 1 New England
A26: =IFERROR(INDEX(NEMS_mapping!C$3:C$12,MATCH(NEMS_residential!D26,NEMS_mapping!B$3:B$12,0)),A25) -> cooling and ventilation | G26: Sum of TOTPURCHASE | H26: 22003 | I26: 23229 | J26: 23447 | K26: 24386 | L26: 24692 | M26: 25480 | N26: 5700 | O26: 10516 | P26: 11103 | Q26: 11110 | R26: 10678 | S26: 10425 | T26: 10098 | U26: 9704 | V26: 9270 | W26: 8846 | X26: 8495 | Y26: 63575 | Z26: 64294 | AA26: 66087 | AB26: 66972 | AC26: 67539 | AD26: 70960 | AE26: 74063 | AF26: 76732 | AG26: 78861 | AH26: 80581 | AI26: 81889 | AJ26: 83220 | AK26: 84033 | AL26: 84564 | AM26: 85266 | AN26: 85698 | AO26: 86635 | AP26: 87534 | DH26: =IF(B26<>"", B26, DH25) -> 1 New England
A27: =IFERROR(INDEX(NEMS_mapping!C$3:C$12,MATCH(NEMS_residential!D27,NEMS_mapping!B$3:B$12,0)),A26) -> cooling and ventilation | G27: Sum of TOTINVEST | H27: 49508464 | I27: 52266464 | J27: 52756280 | K27: 54870092 | L27: 55558396 | M27: 57331168 | N27: 12826356 | O27: 24714711 | P27: 26095446 | Q27: 26110806 | R27: 25096064 | S27: 24500959 | T27: 23734432 | U27: 22806647 | V27: 21786009 | W27: 20791232 | X27: 19966792 | Y27: 149402930 | Z27: 151094066 | AA27: 155305968 | AB27: 157387042 | AC27: 158718134 | AD27: 166758980 | AE27: 174048834 | AF27: 180323550 | AG27: 185325724 | AH27: 189367356 | AI27: 192442210 | AJ27: 195569696 | AK27: 197479024 | AL27: 198726482 | AM27: 200377924 | AN27: 201391490 | AO27: 203595810 | AP27: 205706180 | DH27: =IF(B27<>"", B27, DH26) -> 1 New England
A28: =IFERROR(INDEX(NEMS_mapping!C$3:C$12,MATCH(NEMS_residential!D28,NEMS_mapping!B$3:B$12,0)),A27) -> cooling and ventilation | F28: CENT_AIR3 | G28: Sum of TOTSUBSIDY | H28: 0 | I28: 0 | J28: 0 | K28: 0 | L28: 0 | M28: 0 | N28: 0 | O28: 99500784 | P28: 97463464 | Q28: 96222488 | R28: 95053144 | S28: 94450512 | T28: 94296888 | U28: 95523840 | V28: 96982424 | W28: 98888480 | X28: 101717968 | Y28: 0 | Z28: 0 | AA28: 0 | AB28: 0 | AC28: 0 | AD28: 0 | AE28: 0 | AF28: 0 | AG28: 0 | AH28: 0 | AI28: 0 | AJ28: 0 | AK28: 0 | AL28: 0 | AM28: 0 | AN28: 0 | AO28: 0 | AP28: 0 | DH28: =IF(B28<>"", B28, DH27) -> 1 New England
A29: =IFERROR(INDEX(NEMS_mapping!C$3:C$12,MATCH(NEMS_residential!D29,NEMS_mapping!B$3:B$12,0)),A28) -> cooling and ventilation | G29: Sum of TOTPURCHASE | H29: 14957 | I29: 14987 | J29: 16666 | K29: 16521 | L29: 17242 | M29: 17725 | N29: 5920 | O29: 55463 | P29: 54301 | Q29: 53964 | R29: 53487 | S29: 53246 | T29: 53406 | U29: 54237 | V29: 55093 | W29: 56177 | X29: 57745 | Y29: 26836 | Z29: 28194 | AA29: 29357 | AB29: 30705 | AC29: 31579 | AD29: 33925 | AE29: 35993 | AF29: 37911 | AG29: 39572 | AH29: 40841 | AI29: 41947 | AJ29: 42723 | AK29: 43487 | AL29: 44193 | AM29: 44742 | AN29: 45385 | AO29: 45845 | AP29: 46431 | DH29: =IF(B29<>"", B29, DH28) -> 1 New England
A30: =IFERROR(INDEX(NEMS_mapping!C$3:C$12,MATCH(NEMS_residential!D30,NEMS_mapping!B$3:B$12,0)),A29) -> cooling and ventilation | G30: Sum of TOTINVEST | H30: 39639391 | I30: 39716706 | J30: 44166657 | K30: 43784215 | L30: 45694953 | M30: 46972913 | N30: 15690186 | O30: 156776548 | P30: 153495648 | Q30: 152540499 | R30: 151193302 | S30: 150511106 | T30: 150964026 | U30: 153315258 | V30: 155732396 | W30: 158796388 | X30: 163229978 | Y30: 75858217 | Z30: 79697586 | AA30: 82985799 | AB30: 86795467 | AC30: 89266299 | AD30: 95896771 | AE30: 101743217 | AF30: 107165063 | AG30: 111859434 | AH30: 115446247 | AI30: 118571137 | AJ30: 120766854 | AK30: 122925036 | AL30: 124921916 | AM30: 126472659 | AN30: 128290463 | AO30: 129589490 | AP30: 131245455 | DH30: =IF(B30<>"", B30, DH29) -> 1 New England
A31: =IFERROR(INDEX(NEMS_mapping!C$3:C$12,MATCH(NEMS_residential!D31,NEMS_mapping!B$3:B$12,0)),A30) -> cooling and ventilation | F31: CENT_AIR4 | G31: Sum of TOTSUBSIDY | H31: 6181201 | I31: 5637911 | J31: 7001921 | K31: 6444983 | L31: 7180935 | M31: 7048536 | N31: 152886017 | O31: 79409831 | P31: 78860931 | Q31: 77949493 | R31: 77085333 | S31: 76691551 | T31: 76685796 | U31: 77820923 | V31: 79107480 | W31: 80805426 | X31: 83301022 | Y31: 3411219 | Z31: 3612210 | AA31: 3756688 | AB31: 3952178 | AC31: 4070831 | AD31: 4398179 | AE31: 4685214 | AF31: 4950969 | AG31: 5184054 | AH31: 5362957 | AI31: 5520221 | AJ31: 5619067 | AK31: 5727850 | AL31: 5835929 | AM31: 5913992 | AN31: 6018974 | AO31: 6081296 | AP31: 6167990 | DH31: =IF(B31<>"", B31, DH30) -> 1 New England
A32: =IFERROR(INDEX(NEMS_mapping!C$3:C$12,MATCH(NEMS_residential!D32,NEMS_mapping!B$3:B$12,0)),A31) -> cooling and ventilation | G32: Sum of TOTPURCHASE | H32: 12900 | I32: 11806 | J32: 14655 | K32: 13518 | L32: 15005 | M32: 14783 | N32: 70955 | O32: 37564 | P32: 37267 | Q32: 36894 | R32: 36513 | S32: 36382 | T32: 36427 | U32: 36994 | V32: 37607 | W32: 38415 | X32: 39598 | Y32: 18707 | Z32: 19809 | AA32: 20602 | AB32: 21675 | AC32: 22328 | AD32: 24120 | AE32: 25692 | AF32: 27148 | AG32: 28426 | AH32: 29405 | AI32: 30268 | AJ32: 30809 | AK32: 31405 | AL32: 31997 | AM32: 32424 | AN32: 32997 | AO32: 33336 | AP32: 33810 | DH32: =IF(B32<>"", B32, DH31) -> 1 New England
A33: =IFERROR(INDEX(NEMS_mapping!C$3:C$12,MATCH(NEMS_residential!D33,NEMS_mapping!B$3:B$12,0)),A32) -> cooling and ventilation | G33: Sum of TOTINVEST | H33: 41285131 | I33: 37782671 | J33: 46899273 | K33: 43258316 | L33: 48019042 | M33: 47309047 | N33: 227057751 | O33: 120208331 | P33: 119260000 | Q33: 118063328 | R33: 116845514 | S33: 116425975 | T33: 116566940 | U33: 118382208 | V33: 120343831 | W33: 122934127 | X33: 126716478 | Y33: 59865746 | Z33: 63391370 | AA33: 65929672 | AB33: 69363808 | AC33: 71451514 | AD33: 77188613 | AE33: 82217869 | AF33: 86879311 | AG33: 90968089 | AH33: 94101342 | AI33: 96858445 | AJ33: 98591049 | AK33: 100498527 | AL33: 102392390 | AM33: 103758398 | AN33: 105594127 | AO33: 106680434 | AP33: 108193854 | DH33: =IF(B33<>"", B33, DH32) -> 1 New England
A34: =IFERROR(INDEX(NEMS_mapping!C$3:C$12,MATCH(NEMS_residential!D34,NEMS_mapping!B$3:B$12,0)),A33) -> cooling and ventilation | F34: ELEC_HP1 | G34: Sum of TOTSUBSIDY | H34: 0 | I34: 0 | J34: 0 | K34: 0 | L34: 0 | M34: 0 | N34: 0 | O34: 0 | P34: 0 | Q34: 0 | R34: 0 | S34: 0 | T34: 0 | U34: 0 | V34: 0 | W34: 0 | X34: 0 | Y34: 0 | Z34: 0 | AA34: 0 | AB34: 0 | AC34: 0 | AD34: 0 | AE34: 0 | AF34: 0 | AG34: 0 | AH34: 0 | AI34: 0 | AJ34: 0 | AK34: 0 | AL34: 0 | AM34: 0 | AN34: 0 | AO34: 0 | AP34: 0 | DH34: =IF(B34<>"", B34, DH33) -> 1 New England
A35: =IFERROR(INDEX(NEMS_mapping!C$3:C$12,MATCH(NEMS_residential!D35,NEMS_mapping!B$3:B$12,0)),A34) -> cooling and ventilation | G35: Sum of TOTPURCHASE | H35: 1245 | I35: 1832 | J35: 2091 | K35: 2141 | L35: 2112 | M35: 2019 | N35: 123 | O35: 0 | P35: 0 | Q35: 0 | R35: 0 | S35: 0 | T35: 0 | U35: 0 | V35: 0 | W35: 0 | X35: 0 | Y35: 0 | Z35: 0 | AA35: 0 | AB35: 0 | AC35: 0 | AD35: 0 | AE35: 0 | AF35: 0 | AG35: 0 | AH35: 0 | AI35: 0 | AJ35: 0 | AK35: 0 | AL35: 0 | AM35: 0 | AN35: 0 | AO35: 0 | AP35: 0 | DH35: =IF(B35<>"", B35, DH34) -> 1 New England
A36: =IFERROR(INDEX(NEMS_mapping!C$3:C$12,MATCH(NEMS_residential!D36,NEMS_mapping!B$3:B$12,0)),A35) -> cooling and ventilation | G36: Sum of TOTINVEST | H36: 0 | I36: 0 | J36: 0 | K36: 0 | L36: 0 | M36: 0 | N36: 0 | O36: 0 | P36: 0 | Q36: 0 | R36: 0 | S36: 0 | T36: 0 | U36: 0 | V36: 0 | W36: 0 | X36: 0 | Y36: 0 | Z36: 0 | AA36: 0 | AB36: 0 | AC36: 0 | AD36: 0 | AE36: 0 | AF36: 0 | AG36: 0 | AH36: 0 | AI36: 0 | AJ36: 0 | AK36: 0 | AL36: 0 | AM36: 0 | AN36: 0 | AO36: 0 | AP36: 0 | DH36: =IF(B36<>"", B36, DH35) -> 1 New England
A37: =IFERROR(INDEX(NEMS_mapping!C$3:C$12,MATCH(NEMS_residential!D37,NEMS_mapping!B$3:B$12,0)),A36) -> cooling and ventilation | F37: ELEC_HP2 | G37: Sum of TOTSUBSIDY | H37: 215943 | I37: 217890 | J37: 227293 | K37: 231872 | L37: 222651 | M37: 223912 | N37: 22227 | O37: 2034452 | P37: 2010121 | Q37: 2050998 | R37: 2110849 | S37: 2127412 | T37: 2147006 | U37: 2173957 | V37: 2209561 | W37: 2277324 | X37: 2346062 | Y37: 0 | Z37: 0 | AA37: 0 | AB37: 0 | AC37: 0 | AD37: 0 | AE37: 0 | AF37: 0 | AG37: 0 | AH37: 0 | AI37: 0 | AJ37: 0 | AK37: 0 | AL37: 0 | AM37: 0 | AN37: 0 | AO37: 0 | AP37: 0 | DH37: =IF(B37<>"", B37, DH36) -> 1 New England
A38: =IFERROR(INDEX(NEMS_mapping!C$3:C$12,MATCH(NEMS_residential!D38,NEMS_mapping!B$3:B$12,0)),A37) -> cooling and ventilation | G38: Sum of TOTPURCHASE | H38: 1439 | I38: 1452 | J38: 1515 | K38: 1545 | L38: 1484 | M38: 1492 | N38: 148 | O38: 2034 | P38: 2010 | Q38: 2050 | R38: 2110 | S38: 2127 | T38: 2147 | U38: 2173 | V38: 2209 | W38: 2277 | X38: 2346 | Y38: 2425 | Z38: 2502 | AA38: 2589 | AB38: 2656 | AC38: 2692 | AD38: 2757 | AE38: 2808 | AF38: 2850 | AG38: 2907 | AH38: 3015 | AI38: 3118 | AJ38: 3192 | AK38: 3268 | AL38: 3341 | AM38: 3433 | AN38: 3516 | AO38: 3573 | AP38: 3630 | DH38: =IF(B38<>"", B38, DH37) -> 1 New England
A39: =IFERROR(INDEX(NEMS_mapping!C$3:C$12,MATCH(NEMS_residential!D39,NEMS_mapping!B$3:B$12,0)),A38) -> cooling and ventilation | G39: Sum of TOTINVEST | H39: 0 | I39: 0 | J39: 0 | K39: 0 | L39: 0 | M39: 0 | N39: 0 | O39: 0 | P39: 0 | Q39: 0 | R39: 0 | S39: 0 | T39: 0 | U39: 0 | V39: 0 | W39: 0 | X39: 0 | Y39: 0 | Z39: 0 | AA39: 0 | AB39: 0 | AC39: 0 | AD39: 0 | AE39: 0 | AF39: 0 | AG39: 0 | AH39: 0 | AI39: 0 | AJ39: 0 | AK39: 0 | AL39: 0 | AM39: 0 | AN39: 0 | AO39: 0 | AP39: 0 | DH39: =IF(B39<>"", B39, DH38) -> 1 New England
A40: =IFERROR(INDEX(NEMS_mapping!C$3:C$12,MATCH(NEMS_residential!D40,NEMS_mapping!B$3:B$12,0)),A39) -> cooling and ventilation | F40: ELEC_HP3 | G40: Sum of TOTSUBSIDY | H40: 8447128 | I40: 9997430 | J40: 10349171 | K40: 10483677 | L40: 10173277 | M40: 10289977 | N40: 25689201 | O40: 22562688 | P40: 22456733 | Q40: 22827060 | R40: 23426805 | S40: 23562900 | T40: 23743223 | U40: 24006586 | V40: 24345259 | W40: 25063555 | X40: 25794458 | Y40: 11005203 | Z40: 11359694 | AA40: 11725120 | AB40: 12028626 | AC40: 12150178 | AD40: 12329666 | AE40: 12528579 | AF40: 12678476 | AG40: 12885129 | AH40: 13358224 | AI40: 13788478 | AJ40: 14211869 | AK40: 14562952 | AL40: 14872304 | AM40: 15301935 | AN40: 15657733 | AO40: 16015149 | AP40: 16266304 | DH40: =IF(B40<>"", B40, DH39) -> 1 New England
...

Sheet NEMS_commercial
B2: Billions of 2017$
B4: Capital Invest: total installed capital cost of major end-use equipment paid by consumer (excludes federal or utility incentives)
B5: Subsidy Invest: federal equipment subsidies (e.g., investment tax credits for solar water heaters and ground-source heat pumps)
B7: Sum of Amount | E7: Year
B8: Division | C8: EndUse | D8: Label | E8: 2013 | F8: 2014 | G8: 2015 | H8: 2016 | I8: 2017 | J8: 2018 | K8: 2019 | L8: 2020 | M8: 2021 | N8: 2022 | O8: 2023 | P8: 2024 | Q8: 2025 | R8: 2026 | S8: 2027 | T8: 2028 | U8: 2029 | V8: 2030 | W8: 2031 | X8: 2032 | Y8: 2033 | Z8: 2034 | AA8: 2035 | AB8: 2036 | AC8: 2037 | AD8: 2038 | AE8: 2039 | AF8: 2040 | AG8: 2041 | AH8: 2042 | AI8: 2043 | AJ8: 2044 | AK8: 2045 | AL8: 2046 | AM8: 2047 | AN8: 2048 | AO8: 2049 | AP8: 2050 | AQ8: division_filled
A9: =IFERROR(INDEX(NEMS_mapping!C$15:C$29,MATCH(C9,NEMS_mapping!B$15:B$29,0)),"") -> 0 | B9: 1 New England | C9: 1 Heating | D9: Capital Invest | E9: 0.344181 | F9: 0.331865 | G9: 0.28265 | H9: 0.274544 | I9: 0.274712 | J9: 0.237545 | K9: 0.240459 | L9: 0.225642 | M9: 0.229639 | N9: 0.23404 | O9: 0.230791 | P9: 0.22569 | Q9: 0.219426 | R9: 0.213868 | S9: 0.209877 | T9: 0.209018 | U9: 0.208821 | V9: 0.207567 | W9: 0.206389 | X9: 0.203335 | Y9: 0.22554 | Z9: 0.220431 | AA9: 0.21528 | AB9: 0.210423 | AC9: 0.205495 | AD9: 0.200619 | AE9: 0.196272 | AF9: 0.192011 | AG9: 0.188216 | AH9: 0.184726 | AI9: 0.181251 | AJ9: 0.177932 | AK9: 0.17494 | AL9: 0.171769 | AM9: 0.168794 | AN9: 0.166058 | AO9: 0.163078 | AP9: 0.160389 | AQ9: =B9 -> 1 New England
A10: =IFERROR(INDEX(NEMS_mapping!C$15:C$29,MATCH(C10,NEMS_mapping!B$15:B$29,0)),"") | D10: Tot Subsidy Inv | E10: 0.040291 | F10: 0.039495 | G10: 0.034441 | H10: 0.033283 | I10: 0.032725 | J10: 0.024715 | K10: 0.02419 | L10: 0.032051 | M10: 0.031314 | N10: 0.031243 | O10: 0.091871 | P10: 0.09045 | Q10: 0.089599 | R10: 0.089298 | S10: 0.089161 | T10: 0.089042 | U10: 0.090349 | V10: 0.090049 | W10: 0.090608 | X10: 0.090822 | Y10: 0.014215 | Z10: 0.013741 | AA10: 0.013309 | AB10: 0.012899 | AC10: 0.01223 | AD10: 0.011552 | AE10: 0.011192 | AF10: 0.010764 | AG10: 0.01043 | AH10: 0.010132 | AI10: 0.009695 | AJ10: 0.009396 | AK10: 0.009139 | AL10: 0.008885 | AM10: 0.008615 | AN10: 0.008389 | AO10: 0.00816 | AP10: 0.007948 | AQ10: =IF(B10<>"", B10, AQ9) -> 1 New England
A11: =IFERROR(INDEX(NEMS_mapping!C$15:C$29,MATCH(C11,NEMS_mapping!B$15:B$29,0)),"") -> heating | C11: 1 Heating Total | E11: 0.384472 | F11: 0.37136 | G11: 0.317091 | H11: 0.307827 | I11: 0.307437 | J11: 0.26226 | K11: 0.264649 | L11: 0.257693 | M11: 0.260953 | N11: 0.265283 | O11: 0.322662 | P11: 0.31614 | Q11: 0.309025 | R11: 0.303166 | S11: 0.299038 | T11: 0.29806 | U11: 0.29917 | V11: 0.297616 | W11: 0.296997 | X11: 0.294157 | Y11: 0.239755 | Z11: 0.234172 | AA11: 0.228589 | AB11: 0.223322 | AC11: 0.217725 | AD11: 0.212171 | AE11: 0.207464 | AF11: 0.202775 | AG11: 0.198646 | AH11: 0.194858 | AI11: 0.190946 | AJ11: 0.187328 | AK11: 0.184079 | AL11: 0.180654 | AM11: 0.177409 | AN11: 0.174447 | AO11: 0.171238 | AP11: 0.168337 | AQ11: =IF(B11<>"", B11, AQ10) -> 1 New England
A12: =IFERROR(INDEX(NEMS_mapping!C$15:C$29,MATCH(C12,NEMS_mapping!B$15:B$29,0)),"") -> 0 | C12: 2 Cooling | D12: Capital Invest | E12: 0.459549 | F12: 0.250312 | G12: 0.270012 | H12: 0.264214 | I12: 0.25006 | J12: 0.257265 | K12: 0.264678 | L12: 0.254914 | M12: 0.254714 | N12: 0.251159 | O12: 0.258645 | P12: 0.25721 | Q12: 0.260611 | R12: 0.256828 | S12: 0.25443 | T12: 0.256565 | U12: 0.259006 | V12: 0.261049 | W12: 0.262179 | X12: 0.261104 | Y12: 0.261881 | Z12: 0.259144 | AA12: 0.256238 | AB12: 0.253421 | AC12: 0.251026 | AD12: 0.248606 | AE12: 0.246351 | AF12: 0.244633 | AG12: 0.243069 | AH12: 0.241987 | AI12: 0.241094 | AJ12: 0.240521 | AK12: 0.240239 | AL12: 0.239928 | AM12: 0.239896 | AN12: 0.239742 | AO12: 0.239743 | AP12: 0.239565 | AQ12: =IF(B12<>"", B12, AQ11) -> 1 New England
A13: =IFERROR(INDEX(NEMS_mapping!C$15:C$29,MATCH(C13,NEMS_mapping!B$15:B$29,0)),"") | D13: Tot Subsidy Inv | E13: 0.009266 | F13: 0.008442 | G13: 0.010826 | H13: 0.010124 | I13: 0.0071 | J13: 0.010742 | K13: 0.007896 | L13: 0.008899 | M13: 0.008329 | N13: 0.008734 | O13: 0.013037 | P13: 0.01713 | Q13: 0.016044 | R13: 0.016028 | S13: 0.016286 | T13: 0.01692 | U13: 0.017724 | V13: 0.019027 | W13: 0.019597 | X13: 0.020102 | Y13: 0.009436 | Z13: 0.009466 | AA13: 0.009361 | AB13: 0.009372 | AC13: 0.00935 | AD13: 0.009369 | AE13: 0.009339 | AF13: 0.009747 | AG13: 0.009742 | AH13: 0.009782 | AI13: 0.009819 | AJ13: 0.009885 | AK13: 0.009957 | AL13: 0.010031 | AM13: 0.010137 | AN13: 0.010215 | AO13: 0.010317 | AP13: 0.010387 | AQ13: =IF(B13<>"", B13, AQ12) -> 1 New England
A14: =IFERROR(INDEX(NEMS_mapping!C$15:C$29,MATCH(C14,NEMS_mapping!B$15:B$29,0)),"") -> cooling and ventilation | C14: 2 Cooling Total | E14: 0.468815 | F14: 0.258754 | G14: 0.280838 | H14: 0.274338 | I14: 0.25716 | J14: 0.268007 | K14: 0.272574 | L14: 0.263813 | M14: 0.263043 | N14: 0.259893 | O14: 0.271682 | P14: 0.27434 | Q14: 0.276655 | R14: 0.272856 | S14: 0.270716 | T14: 0.273485 | U14: 0.27673 | V14: 0.280076 | W14: 0.281776 | X14: 0.281206 | Y14: 0.271317 | Z14: 0.26861 | AA14: 0.265599 | AB14: 0.262793 | AC14: 0.260376 | AD14: 0.257975 | AE14: 0.25569 | AF14: 0.25438 | AG14: 0.252811 | AH14: 0.251769 | AI14: 0.250913 | AJ14: 0.250406 | AK14: 0.250196 | AL14: 0.249959 | AM14: 0.250033 | AN14: 0.249957 | AO14: 0.25006 | AP14: 0.249952 | AQ14: =IF(B14<>"", B14, AQ13) -> 1 New England
A15: =IFERROR(INDEX(NEMS_mapping!C$15:C$29,MATCH(C15,NEMS_mapping!B$15:B$29,0)),"") -> 0 | C15: 3 Water Heating | D15: Capital Invest | E15: 0.01449 | F15: 0.014314 | G15: 0.014585 | H15: 0.014826 | I15: 0.014597 | J15: 0.014882 | K15: 0.015203 | L15: 0.015069 | M15: 0.01514 | N15: 0.015929 | O15: 0.015414 | P15: 0.015225 | Q15: 0.015488 | R15: 0.015373 | S15: 0.016097 | T15: 0.016293 | U15: 0.016504 | V15: 0.016685 | W15: 0.016838 | X15: 0.016887 | Y15: 0.016861 | Z15: 0.016946 | AA15: 0.016841 | AB15: 0.016821 | AC15: 0.016794 | AD15: 0.016726 | AE15: 0.016657 | AF15: 0.016594 | AG15: 0.016554 | AH15: 0.016525 | AI15: 0.016506 | AJ15: 0.016498 | AK15: 0.016496 | AL15: 0.016498 | AM15: 0.016503 | AN15: 0.016508 | AO15: 0.016473 | AP15: 0.016476 | AQ15: =IF(B15<>"", B15, AQ14) -> 1 New England
A16: =IFERROR(INDEX(NEMS_mapping!C$15:C$29,MATCH(C16,NEMS_mapping!B$15:B$29,0)),"") | D16: Tot Subsidy Inv | E16: 0.003698 | F16: 0.003616 | G16: 0.003664 | H16: 0.003758 | I16: 0.003847 | J16: 0.004531 | K16: 0.004642 | L16: 0.003924 | M16: 0.003966 | N16: 0.00484 | O16: 0.007164 | P16: 0.006217 | Q16: 0.006309 | R16: 0.00616 | S16: 0.003603 | T16: 0.003664 | U16: 0.003728 | V16: 0.003785 | W16: 0.003834 | X16: 0.003859 | Y16: 0.003866 | Z16: 0.00395 | AA16: 0.003928 | AB16: 0.003945 | AC16: 0.003969 | AD16: 0.003965 | AE16: 0.003959 | AF16: 0.003955 | AG16: 0.003954 | AH16: 0.003958 | AI16: 0.003962 | AJ16: 0.003968 | AK16: 0.003976 | AL16: 0.003984 | AM16: 0.003992 | AN16: 0.003999 | AO16: 0.003979 | AP16: 0.003984 | AQ16: =IF(B16<>"", B16, AQ15) -> 1 New England
A17: =IFERROR(INDEX(NEMS_mapping!C$15:C$29,MATCH(C17,NEMS_mapping!B$15:B$29,0)),"") -> appliances | C17: 3 Water Heating Total | E17: 0.018188 | F17: 0.01793 | G17: 0.018249 | H17: 0.018584 | I17: 0.018444 | J17: 0.019413 | K17: 0.019845 | L17: 0.018993 | M17: 0.019106 | N17: 0.020769 | O17: 0.022578 | P17: 0.021442 | Q17: 0.021797 | R17: 0.021533 | S17: 0.0197 | T17: 0.019957 | U17: 0.020232 | V17: 0.02047 | W17: 0.020672 | X17: 0.020746 | Y17: 0.020727 | Z17: 0.020896 | AA17: 0.020769 | AB17: 0.020766 | AC17: 0.020763 | AD17: 0.020691 | AE17: 0.020616 | AF17: 0.020549 | AG17: 0.020508 | AH17: 0.020483 | AI17: 0.020468 | AJ17: 0.020466 | AK17: 0.020472 | AL17: 0.020482 | AM17: 0.020495 | AN17: 0.020507 | AO17: 0.020452 | AP17: 0.02046 | AQ17: =IF(B17<>"", B17, AQ16) -> 1 New England
A18: =IFERROR(INDEX(NEMS_mapping!C$15:C$29,MATCH(C18,NEMS_mapping!B$15:B$29,0)),"") -> 0 | C18: 4 Ventilation | D18: Capital Invest | E18: 0.241285 | F18: 0.235502 | G18: 0.228035 | H18: 0.223234 | I18: 0.21545 | J18: 0.210189 | K18: 0.206863 | L18: 0.201924 | M18: 0.200704 | N18: 0.193861 | O18: 0.19003 | P18: 0.188356 | Q18: 0.186841 | R18: 0.180743 | S18: 0.175589 | T18: 0.173059 | U18: 0.170695 | V18: 0.166102 | W18: 0.163166 | X18: 0.159169 | Y18: 0.154574 | Z18: 0.150118 | AA18: 0.145748 | AB18: 0.141586 | AC18: 0.137727 | AD18: 0.134021 | AE18: 0.130497 | AF18: 0.12721 | AG18: 0.124219 | AH18: 0.121452 | AI18: 0.118902 | AJ18: 0.116523 | AK18: 0.114286 | AL18: 0.112164 | AM18: 0.110128 | AN18: 0.108161 | AO18: 0.106248 | AP18: 0.104376 | AQ18: =IF(B18<>"", B18, AQ17) -> 1 New England
A19: =IFERROR(INDEX(NEMS_mapping!C$15:C$29,MATCH(C19,NEMS_mapping!B$15:B$29,0)),"") | D19: Tot Subsidy Inv | E19: 0 | F19: 0 | G19: 0 | H19: 0 | I19: 0 | J19: 0 | K19: 0 | L19: 0 | M19: 0 | N19: 2e-05 | O19: 2e-05 | P19: 2e-05 | Q19: 7e-06 | R19: 7e-06 | S19: 7e-06 | T19: 6e-06 | U19: 6e-06 | V19: 0.013241 | W19: 0.013024 | X19: 0.012719 | Y19: 0.012366 | Z19: 0.012024 | AA19: 0.011689 | AB19: 0.011371 | AC19: 0.011078 | AD19: 0.010797 | AE19: 0.010532 | AF19: 0.010286 | AG19: 0.010064 | AH19: 0.00986 | AI19: 0.009675 | AJ19: 0.009504 | AK19: 0.009345 | AL19: 0.009196 | AM19: 0.009054 | AN19: 0.008917 | AO19: 0.008786 | AP19: 0.008658 | AQ19: =IF(B19<>"", B19, AQ18) -> 1 New England
A20: =IFERROR(INDEX(NEMS_mapping!C$15:C$29,MATCH(C20,NEMS_mapping!B$15:B$29,0)),"") -> appliances | C20: 4 Ventilation Total | E20: 0.241285 | F20: 0.235502 | G20: 0.228035 | H20: 0.223234 | I20: 0.21545 | J20: 0.210189 | K20: 0.206863 | L20: 0.201924 | M20: 0.200704 | N20: 0.193881 | O20: 0.19005 | P20: 0.188376 | Q20: 0.186848 | R20: 0.18075 | S20: 0.175596 | T20: 0.173065 | U20: 0.170701 | V20: 0.179343 | W20: 0.17619 | X20: 0.171888 | Y20: 0.16694 | Z20: 0.162142 | AA20: 0.157437 | AB20: 0.152957 | AC20: 0.148805 | AD20: 0.144818 | AE20: 0.141029 | AF20: 0.137496 | AG20: 0.134283 | AH20: 0.131312 | AI20: 0.128577 | AJ20: 0.126027 | AK20: 0.123631 | AL20: 0.12136 | AM20: 0.119182 | AN20: 0.117078 | AO20: 0.115034 | AP20: 0.113034 | AQ20: =IF(B20<>"", B20, AQ19) -> 1 New England
A21: =IFERROR(INDEX(NEMS_mapping!C$15:C$29,MATCH(C21,NEMS_mapping!B$15:B$29,0)),"") -> 0 | C21: 5 Cooking | D21: Capital Invest | E21: 0.046835 | F21: 0.046846 | G21: 0.046573 | H21: 0.046745 | I21: 0.046025 | J21: 0.045877 | K21: 0.046728 | L21: 0.045887 | M21: 0.045674 | N21: 0.045422 | O21: 0.046172 | P21: 0.046801 | Q21: 0.047522 | R21: 0.047134 | S21: 0.046903 | T21: 0.047272 | U21: 0.047687 | V21: 0.048014 | W21: 0.048263 | X21: 0.048203 | Y21: 0.047926 | Z21: 0.047626 | AA21: 0.047276 | AB21: 0.046929 | AC21: 0.046607 | AD21: 0.046276 | AE21: 0.045947 | AF21: 0.045642 | AG21: 0.045402 | AH21: 0.045198 | AI21: 0.04503 | AJ21: 0.044891 | AK21: 0.044773 | AL21: 0.04467 | AM21: 0.044573 | AN21: 0.044477 | AO21: 0.044373 | AP21: 0.044266 | AQ21: =IF(B21<>"", B21, AQ20) -> 1 New England
A22: =IFERROR(INDEX(NEMS_mapping!C$15:C$29,MATCH(C22,NEMS_mapping!B$15:B$29,0)),"") | D22: Tot Subsidy Inv | E22: 0 | F22: 0 | G22: 0 | H22: 0 | I22: 0 | J22: 0 | K22: 0 | L22: 0 | M22: 0 | N22: 0 | O22: 0 | P22: 0 | Q22: 0 | R22: 0 | S22: 0 | T22: 0 | U22: 0 | V22: 0 | W22: 0 | X22: 0 | Y22: 0 | Z22: 0 | AA22: 0 | AB22: 0 | AC22: 0 | AD22: 0 | AE22: 0 | AF22: 0 | AG22: 0 | AH22: 0 | AI22: 0 | AJ22: 0 | AK22: 0 | AL22: 0 | AM22: 0 | AN22: 0 | AO22: 0 | AP22: 0 | AQ22: =IF(B22<>"", B22, AQ21) -> 1 New England
A23: =IFERROR(INDEX(NEMS_mapping!C$15:C$29,MATCH(C23,NEMS_mapping!B$15:B$29,0)),"") -> appliances | C23: 5 Cooking Total | E23: 0.046835 | F23: 0.046846 | G23: 0.046573 | H23: 0.046745 | I23: 0.046025 | J23: 0.045877 | K23: 0.046728 | L23: 0.045887 | M23: 0.045674 | N23: 0.045422 | O23: 0.046172 | P23: 0.046801 | Q23: 0.047522 | R23: 0.047134 | S23: 0.046903 | T23: 0.047272 | U23: 0.047687 | V23: 0.048014 | W23: 0.048263 | X23: 0.048203 | Y23: 0.047926 | Z23: 0.047626 | AA23: 0.047276 | AB23: 0.046929 | AC23: 0.046607 | AD23: 0.046276 | AE23: 0.045947 | AF23: 0.045642 | AG23: 0.045402 | AH23: 0.045198 | AI23: 0.04503 | AJ23: 0.044891 | AK23: 0.044773 | AL23: 0.04467 | AM23: 0.044573 | AN23: 0.044477 | AO23: 0.044373 | AP23: 0.044266 | AQ23: =IF(B23<>"", B23, AQ22) -> 1 New England
A24: =IFERROR(INDEX(NEMS_mapping!C$15:C$29,MATCH(C24,NEMS_mapping!B$15:B$29,0)),"") -> 0 | C24: 6 Lighting | D24: Capital Invest | E24: 0.062374 | F24: 0.055478 | G24: 0.052881 | H24: 0.046429 | I24: 0.040458 | J24: 0.035856 | K24: 0.032791 | L24: 0.029545 | M24: 0.026433 | N24: 0.03935 | O24: 0.039534 | P24: 0.039622 | Q24: 0.040465 | R24: 0.040502 | S24: 0.040325 | T24: 0.040628 | U24: 0.040964 | V24: 0.043937 | W24: 0.044661 | X24: 0.044434 | Y24: 0.044584 | Z24: 0.044584 | AA24: 0.043936 | AB24: 0.04371 | AC24: 0.043061 | AD24: 0.042666 | AE24: 0.042143 | AF24: 0.043939 | AG24: 0.044146 | AH24: 0.043928 | AI24: 0.043972 | AJ24: 0.044028 | AK24: 0.044114 | AL24: 0.044227 | AM24: 0.044338 | AN24: 0.044458 | AO24: 0.044557 | AP24: 0.044669 | AQ24: =IF(B24<>"", B24, AQ23) -> 1 New England
A25: =IFERROR(INDEX(NEMS_mapping!C$15:C$29,MATCH(C25,NEMS_mapping!B$15:B$29,0)),"") | D25: Tot Subsidy Inv | E25: 0.002874 | F25: 0.002743 | G25: 0.00926 | H25: 0.014804 | I25: 0.015047 | J25: 0.014989 | K25: 0.015282 | L25: 0.015039 | M25: 0.015105 | N25: 0.001547 | O25: 0.001501 | P25: 0.000795 | Q25: 0.000446 | R25: 9.4e-05 | S25: 7e-05 | T25: 4.7e-05 | U25: 2.3e-05 | V25: 0 | W25: 0 | X25: 0 | Y25: 0 | Z25: 0 | AA25: 0 | AB25: 0 | AC25: 0 | AD25: 0 | AE25: 0 | AF25: 0 | AG25: 0 | AH25: 0 | AI25: 0 | AJ25: 0 | AK25: 0 | AL25: 0 | AM25: 0 | AN25: 0 | AO25: 0 | AP25: 0 | AQ25: =IF(B25<>"", B25, AQ24) -> 1 New England
A26: =IFERROR(INDEX(NEMS_mapping!C$15:C$29,MATCH(C26,NEMS_mapping!B$15:B$29,0)),"") -> lighting | C26: 6 Lighting Total | E26: 0.065248 | F26: 0.058221 | G26: 0.062141 | H26: 0.061233 | I26: 0.055505 | J26: 0.050845 | K26: 0.048073 | L26: 0.044584 | M26: 0.041538 | N26: 0.040897 | O26: 0.041035 | P26: 0.040417 | Q26: 0.040911 | R26: 0.040596 | S26: 0.040395 | T26: 0.040675 | U26: 0.040987 | V26: 0.043937 | W26: 0.044661 | X26: 0.044434 | Y26: 0.044584 | Z26: 0.044584 | AA26: 0.043936 | AB26: 0.04371 | AC26: 0.043061 | AD26: 0.042666 | AE26: 0.042143 | AF26: 0.043939 | AG26: 0.044146 | AH26: 0.043928 | AI26: 0.043972 | AJ26: 0.044028 | AK26: 0.044114 | AL26: 0.044227 | AM26: 0.044338 | AN26: 0.044458 | AO26: 0.044557 | AP26: 0.044669 | AQ26: =IF(B26<>"", B26, AQ25) -> 1 New England
A27: =IFERROR(INDEX(NEMS_mapping!C$15:C$29,MATCH(C27,NEMS_mapping!B$15:B$29,0)),"") -> 0 | C27: 7 Refrigeration | D27: Capital Invest | E27: 2.560282 | F27: 2.570202 | G27: 2.557242 | H27: 2.570658 | I27: 2.538752 | J27: 2.573282 | K27: 2.616058 | L27: 2.586092 | M27: 2.573054 | N27: 2.470843 | O27: 2.518917 | P27: 2.562241 | Q27: 2.605556 | R27: 2.593944 | S27: 2.589575 | T27: 2.6152 | U27: 2.643184 | V27: 2.667063 | W27: 2.688585 | X27: 2.694498 | Y27: 2.689013 | Z27: 2.681486 | AA27: 2.671247 | AB27: 2.660178 | AC27: 2.650079 | AD27: 2.639028 | AE27: 2.627667 | AF27: 2.61717 | AG27: 2.610785 | AH27: 2.605925 | AI27: 2.602905 | AJ27: 2.601226 | AK27: 2.600616 | AL27: 2.60078 | AM27: 2.60129 | AN27: 2.601868 | AO27: 2.602266 | AP27: 2.602194 | AQ27: =IF(B27<>"", B27, AQ26) -> 1 New England
A28: =IFERROR(INDEX(NEMS_mapping!C$15:C$29,MATCH(C28,NEMS_mapping!B$15:B$29,0)),"") | D28: Tot Subsidy Inv | E28: 0 | F28: 0 | G28: 0 | H28: 0 | I28: 0 | J28: 0 | K28: 0 | L28: 0 | M28: 0 | N28: 0 | O28: 0 | P28: 0 | Q28: 0 | R28: 0 | S28: 0 | T28: 0 | U28: 0 | V28: 0 | W28: 0 | X28: 0 | Y28: 0 | Z28: 0 | AA28: 0 | AB28: 0 | AC28: 0 | AD28: 0 | AE28: 0 | AF28: 0 | AG28: 0 | AH28: 0 | AI28: 0 | AJ28: 0 | AK28: 0 | AL28: 0 | AM28: 0 | AN28: 0 | AO28: 0 | AP28: 0 | AQ28: =IF(B28<>"", B28, AQ27) -> 1 New England
A29: =IFERROR(INDEX(NEMS_mapping!C$15:C$29,MATCH(C29,NEMS_mapping!B$15:B$29,0)),"") -> appliances | C29: 7 Refrigeration Total | E29: 2.560282 | F29: 2.570202 | G29: 2.557242 | H29: 2.570658 | I29: 2.538752 | J29: 2.573282 | K29: 2.616058 | L29: 2.586092 | M29: 2.573054 | N29: 2.470843 | O29: 2.518917 | P29: 2.562241 | Q29: 2.605556 | R29: 2.593944 | S29: 2.589575 | T29: 2.6152 | U29: 2.643184 | V29: 2.667063 | W29: 2.688585 | X29: 2.694498 | Y29: 2.689013 | Z29: 2.681486 | AA29: 2.671247 | AB29: 2.660178 | AC29: 2.650079 | AD29: 2.639028 | AE29: 2.627667 | AF29: 2.61717 | AG29: 2.610785 | AH29: 2.605925 | AI29: 2.602905 | AJ29: 2.601226 | AK29: 2.600616 | AL29: 2.60078 | AM29: 2.60129 | AN29: 2.601868 | AO29: 2.602266 | AP29: 2.602194 | AQ29: =IF(B29<>"", B29, AQ28) -> 1 New England
A30: =IFERROR(INDEX(NEMS_mapping!C$15:C$29,MATCH(C30,NEMS_mapping!B$15:B$29,0)),"") | B30: 1 New England Total | E30: 3.785125 | F30: 3.558815 | G30: 3.510169 | H30: 3.502619 | I30: 3.438773 | J30: 3.429873 | K30: 3.47479 | L30: 3.418986 | M30: 3.404072 | N30: 3.296988 | O30: 3.413096 | P30: 3.449757 | Q30: 3.488314 | R30: 3.459979 | S30: 3.441923 | T30: 3.467714 | U30: 3.498691 | V30: 3.536519 | W30: 3.557144 | X30: 3.555132 | Y30: 3.480262 | Z30: 3.459516 | AA30: 3.434853 | AB30: 3.410655 | AC30: 3.387416 | AD30: 3.363625 | AE30: 3.340556 | AF30: 3.321951 | AG30: 3.306581 | AH30: 3.293473 | AI30: 3.282811 | AJ30: 3.274372 | AK30: 3.267881 | AL30: 3.262132 | AM30: 3.25732 | AN30: 3.252792 | AO30: 3.24798 | AP30: 3.242912 | AQ30: =IF(B30<>"", B30, AQ29) -> 1 New England Total
A31: =IFERROR(INDEX(NEMS_mapping!C$15:C$29,MATCH(C31,NEMS_mapping!B$15:B$29,0)),"") -> 0 | B31: 2 Middle Atlantic | C31: 1 Heating | D31: Capital Invest | E31: 1.300188 | F31: 1.265178 | G31: 1.239941 | H31: 1.199411 | I31: 1.213989 | J31: 1.049931 | K31: 1.041244 | L31: 1.019009 | M31: 0.998915 | N31: 0.991274 | O31: 1.000369 | P31: 0.982289 | Q31: 0.977043 | R31: 0.951057 | S31: 0.930728 | T31: 0.924898 | U31: 0.919659 | V31: 0.912733 | W31: 0.903926 | X31: 0.889235 | Y31: 0.886864 | Z31: 0.867554 | AA31: 0.848567 | AB31: 0.830266 | AC31: 0.812651 | AD31: 0.796018 | AE31: 0.780413 | AF31: 0.766107 | AG31: 0.752429 | AH31: 0.738775 | AI31: 0.725869 | AJ31: 0.713775 | AK31: 0.702692 | AL31: 0.691921 | AM31: 0.68015 | AN31: 0.669644 | AO31: 0.659283 | AP31: 0.648701 | AQ31: =IF(B31<>"", B31, AQ30) -> 2 Middle Atlantic
A32: =IFERROR(INDEX(NEMS_mapping!C$15:C$29,MATCH(C32,NEMS_mapping!B$15:B$29,0)),"") | D32: Tot Subsidy Inv | E32: 0.073642 | F32: 0.069443 | G32: 0.065535 | H32: 0.062001 | I32: 0.064598 | J32: 0.038081 | K32: 0.038253 | L32: 0.051575 | M32: 0.05097 | N32: 0.051794 | O32: 0.059657 | P32: 0.057403 | Q32: 0.053596 | R32: 0.050809 | S32: 0.049115 | T32: 0.048543 | U32: 0.047979 | V32: 0.047222 | W32: 0.046624 | X32: 0.045853 | Y32: 0.01535 | Z32: 0.014843 | AA32: 0.014502 | AB32: 0.014171 | AC32: 0.013817 | AD32: 0.013513 | AE32: 0.013248 | AF32: 0.012968 | AG32: 0.012811 | AH32: 0.01243 | AI32: 0.01201 | AJ32: 0.011702 | AK32: 0.011488 | AL32: 0.011267 | AM32: 0.010538 | AN32: 0.010284 | AO32: 0.01009 | AP32: 0.009885 | AQ32: =IF(B32<>"", B32, AQ31) -> 2 Middle Atlantic
A33: =IFERROR(INDEX(NEMS_mapping!C$15:C$29,MATCH(C33,NEMS_mapping!B$15:B$29,0)),"") -> heating | C33: 1 Heating Total | E33: 1.37383 | F33: 1.334621 | G33: 1.305476 | H33: 1.261412 | I33: 1.278587 | J33: 1.088012 | K33: 1.079497 | L33: 1.070584 | M33: 1.049885 | N33: 1.043068 | O33: 1.060026 | P33: 1.039692 | Q33: 1.030639 | R33: 1.001866 | S33: 0.979843 | T33: 0.973441 | U33: 0.967638 | V33: 0.959955 | W33: 0.95055 | X33: 0.935088 | Y33: 0.902214 | Z33: 0.882397 | AA33: 0.863069 | AB33: 0.844437 | AC33: 0.826468 | AD33: 0.809531 | AE33: 0.793661 | AF33: 0.779075 | AG33: 0.76524 | AH33: 0.751205 | AI33: 0.737879 | AJ33: 0.725477 | AK33: 0.71418 | AL33: 0.703188 | AM33: 0.690688 | AN33: 0.679928 | AO33: 0.669373 | AP33: 0.658586 | AQ33: =IF(B33<>"", B33, AQ32) -> 2 Middle Atlantic
A34: =IFERROR(INDEX(NEMS_mapping!C$15:C$29,MATCH(C34,NEMS_mapping!B$15:B$29,0)),"") -> 0 | C34: 2 Cooling | D34: Capital Invest | E34: 1.847958 | F34: 0.995834 | G34: 1.108218 | H34: 1.04177 | I34: 1.024655 | J34: 1.109292 | K34: 1.075084 | L34: 1.096808 | M34: 1.052453 | N34: 1.043475 | O34: 1.08129 | P34: 1.091433 | Q34: 1.100519 | R34: 1.086463 | S34: 1.078429 | T34: 1.088811 | U34: 1.100772 | V34: 1.110891 | W34: 1.117475 | X34: 1.115065 | Y34: 1.108573 | Z34: 1.099911 | AA34: 1.091116 | AB34: 1.081854 | AC34: 1.075058 | AD34: 1.068872 | AE34: 1.063183 | AF34: 1.059687 | AG34: 1.057319 | AH34: 1.057122 | AI34: 1.058382 | AJ34: 1.060739 | AK34: 1.064499 | AL34: 1.068855 | AM34: 1.074054 | AN34: 1.080072 | AO34: 1.085939 | AP34: 1.092529 | AQ34: =IF(B34<>"", B34, AQ33) -> 2 Middle Atlantic
A35: =IFERROR(INDEX(NEMS_mapping!C$15:C$29,MATCH(C35,NEMS_mapping!B$15:B$29,0)),"") | D35: Tot Subsidy Inv | E35: 0.052614 | F35: 0.051096 | G35: 0.055292 | H35: 0.050986 | I35: 0.048967 | J35: 0.054951 | K35: 0.052717 | L35: 0.054764 | M35: 0.053757 | N35: 0.052533 | O35: 0.015458 | P35: 0.019019 | Q35: 0.01765 | R35: 0.017155 | S35: 0.017563 | T35: 0.018379 | U35: 0.019173 | V35: 0.021565 | W35: 0.022143 | X35: 0.022449 | Y35: 0.019067 | Z35: 0.019084 | AA35: 0.019674 | AB35: 0.019032 | AC35: 0.019064 | AD35: 0.019551 | AE35: 0.019842 | AF35: 0.020542 | AG35: 0.020645 | AH35: 0.021163 | AI35: 0.02142 | AJ35: 0.021706 | AK35: 0.021719 | AL35: 0.02161 | AM35: 0.02197 | AN35: 0.022366 | AO35: 0.022742 | AP35: 0.023028 | AQ35: =IF(B35<>"", B35, AQ34) -> 2 Middle Atlantic
A36: =IFERROR(INDEX(NEMS_mapping!C$15:C$29,MATCH(C36,NEMS_mapping!B$15:B$29,0)),"") -> cooling and ventilation | C36: 2 Cooling Total | E36: 1.900572 | F36: 1.04693 | G36: 1.16351 | H36: 1.092756 | I36: 1.073622 | J36: 1.164243 | K36: 1.127801 | L36: 1.151572 | M36: 1.10621 | N36: 1.096008 | O36: 1.096748 | P36: 1.110452 | Q36: 1.118169 | R36: 1.103618 | S36: 1.095992 | T36: 1.10719 | U36: 1.119945 | V36: 1.132456 | W36: 1.139618 | X36: 1.137514 | Y36: 1.12764 | Z36: 1.118995 | AA36: 1.11079 | AB36: 1.100886 | AC36: 1.094122 | AD36: 1.088423 | AE36: 1.083025 | AF36: 1.080229 | AG36: 1.077964 | AH36: 1.078285 | AI36: 1.079802 | AJ36: 1.082445 | AK36: 1.086218 | AL36: 1.090465 | AM36: 1.096024 | AN36: 1.102438 | AO36: 1.108681 | AP36: 1.115557 | AQ36: =IF(B36<>"", B36, AQ35) -> 2 Middle Atlantic
A37: =IFERROR(INDEX(NEMS_mapping!C$15:C$29,MATCH(C37,NEMS_mapping!B$15:B$29,0)),"") -> 0 | C37: 3 Water Heating | D37: Capital Invest | E37: 0.126317 | F37: 0.128146 | G37: 0.132459 | H37: 0.134999 | I37: 0.138152 | J37: 0.139722 | K37: 0.141218 | L37: 0.142826 | M37: 0.143058 | N37: 0.142514 | O37: 0.146677 | P37: 0.150863 | Q37: 0.154613 | R37: 0.155013 | S37: 0.156918 | T37: 0.159488 | U37: 0.162178 | V37: 0.164573 | W37: 0.166689 | X37: 0.167808 | Y37: 0.168148 | Z37: 0.16833 | AA37: 0.168315 | AB37: 0.168223 | AC37: 0.168172 | AD37: 0.16823 | AE37: 0.168057 | AF37: 0.167922 | AG37: 0.167975 | AH37: 0.1682 | AI37: 0.168441 | AJ37: 0.168754 | AK37: 0.169125 | AL37: 0.169532 | AM37: 0.169954 | AN37: 0.170372 | AO37: 0.170693 | AP37: 0.171051 | AQ37: =IF(B37<>"", B37, AQ36) -> 2 Middle Atlantic
A38: =IFERROR(INDEX(NEMS_mapping!C$15:C$29,MATCH(C38,NEMS_mapping!B$15:B$29,0)),"") | D38: Tot Subsidy Inv | E38: 0.014485 | F38: 0.014883 | G38: 0.015117 | H38: 0.01534 | I38: 0.016093 | J38: 0.016343 | K38: 0.016594 | L38: 0.016414 | M38: 0.016454 | N38: 0.01674 | O38: 0.020698 | P38: 0.020924 | Q38: 0.021295 | R38: 0.021261 | S38: 0.016773 | T38: 0.017065 | U38: 0.01737 | V38: 0.017642 | W38: 0.017882 | X38: 0.018023 | Y38: 0.018068 | Z38: 0.018097 | AA38: 0.018102 | AB38: 0.018099 | AC38: 0.0181 | AD38: 0.018242 | AE38: 0.01823 | AF38: 0.018221 | AG38: 0.018233 | AH38: 0.018297 | AI38: 0.01833 | AJ38: 0.01837 | AK38: 0.018417 | AL38: 0.018465 | AM38: 0.018515 | AN38: 0.018563 | AO38: 0.018571 | AP38: 0.01861 | AQ38: =IF(B38<>"", B38, AQ37) -> 2 Middle Atlantic
A39: =IFERROR(INDEX(NEMS_mapping!C$15:C$29,MATCH(C39,NEMS_mapping!B$15:B$29,0)),"") -> appliances | C39: 3 Water Heating Total | E39: 0.140802 | F39: 0.143029 | G39: 0.147576 | H39: 0.150339 | I39: 0.154245 | J39: 0.156065 | K39: 0.157812 | L39: 0.15924 | M39: 0.159512 | N39: 0.159254 | O39: 0.167375 | P39: 0.171787 | Q39: 0.175908 | R39: 0.176274 | S39: 0.173691 | T39: 0.176553 | U39: 0.179548 | V39: 0.182215 | W39: 0.184571 | X39: 0.185831 | Y39: 0.186216 | Z39: 0.186427 | AA39: 0.186417 | AB39: 0.186322 | AC39: 0.186272 | AD39: 0.186472 | AE39: 0.186287 | AF39: 0.186143 | AG39: 0.186208 | AH39: 0.186497 | AI39: 0.186771 | AJ39: 0.187124 | AK39: 0.187542 | AL39: 0.187997 | AM39: 0.188469 | AN39: 0.188935 | AO39: 0.189264 | AP39: 0.189661 | AQ39: =IF(B39<>"", B39, AQ38) -> 2 Middle Atlantic
A40: =IFERROR(INDEX(NEMS_mapping!C$15:C$29,MATCH(C40,NEMS_mapping!B$15:B$29,0)),"") -> 0 | C40: 4 Ventilation | D40: Capital Invest | E40: 1.516564 | F40: 1.476081 | G40: 1.463484 | H40: 1.408254 | I40: 1.393922 | J40: 1.383118 | K40: 1.361188 | L40: 1.327955 | M40: 1.297655 | N40: 1.251207 | O40: 1.278188 | P40: 1.263533 | Q40: 1.261601 | R40: 1.224 | S40: 1.193117 | T40: 1.181656 | U40: 1.17134 | V40: 1.141194 | W40: 1.125808 | X40: 1.102259 | Y40: 1.073982 | Z40: 1.046577 | AA40: 1.01965 | AB40: 0.994147 | AC40: 0.97083 | AD40: 0.948544 | AE40: 0.927537 | AF40: 0.908249 | AG40: 0.890972 | AH40: 0.875401 | AI40: 0.861406 | AJ40: 0.848676 | AK40: 0.837004 | AL40: 0.82614 | AM40: 0.815939 | AN40: 0.806218 | AO40: 0.796863 | AP40: 0.787764 | AQ40: =IF(B40<>"", B40, AQ39) -> 2 Middle Atlantic
